const x = 4

console.log(x)

try {
  x = 1
}
catch (e) {
  console.log("x = 1 can't")
}
